{"trial_id": "0", "hyperparameters": {"space": [{"class_name": "Int", "config": {"name": "units1", "default": null, "conditions": [], "min_value": 16, "max_value": 144, "step": 16, "sampling": "linear"}}, {"class_name": "Boolean", "config": {"name": "dropout", "default": false, "conditions": []}}, {"class_name": "Int", "config": {"name": "units2", "default": null, "conditions": [], "min_value": 16, "max_value": 144, "step": 16, "sampling": "linear"}}, {"class_name": "Int", "config": {"name": "units3", "default": null, "conditions": [], "min_value": 16, "max_value": 144, "step": 16, "sampling": "linear"}}], "values": {"units1": 128, "dropout": false, "units2": 96, "units3": 64}}, "metrics": {"metrics": {}}, "score": null, "best_step": 0, "status": "FAILED", "message": "Traceback (most recent call last):\n  File \"c:\\Users\\limfy\\anaconda3\\Lib\\site-packages\\keras_tuner\\src\\engine\\base_tuner.py\", line 274, in _try_run_and_update_trial\n    self._run_and_update_trial(trial, *fit_args, **fit_kwargs)\n  File \"c:\\Users\\limfy\\anaconda3\\Lib\\site-packages\\keras_tuner\\src\\engine\\base_tuner.py\", line 239, in _run_and_update_trial\n    results = self.run_trial(trial, *fit_args, **fit_kwargs)\n              ^^^^^^^^^^^^^^^^^^^^^^^^^^^^^^^^^^^^^^^^^^^^^^\n  File \"c:\\Users\\limfy\\anaconda3\\Lib\\site-packages\\keras_tuner\\src\\engine\\tuner.py\", line 314, in run_trial\n    obj_value = self._build_and_fit_model(trial, *args, **copied_kwargs)\n                ^^^^^^^^^^^^^^^^^^^^^^^^^^^^^^^^^^^^^^^^^^^^^^^^^^^^^^^^\n  File \"c:\\Users\\limfy\\anaconda3\\Lib\\site-packages\\keras_tuner\\src\\engine\\tuner.py\", line 233, in _build_and_fit_model\n    results = self.hypermodel.fit(hp, model, *args, **kwargs)\n              ^^^^^^^^^^^^^^^^^^^^^^^^^^^^^^^^^^^^^^^^^^^^^^^\n  File \"c:\\Users\\limfy\\anaconda3\\Lib\\site-packages\\keras_tuner\\src\\engine\\hypermodel.py\", line 149, in fit\n    return model.fit(*args, **kwargs)\n           ^^^^^^^^^^^^^^^^^^^^^^^^^^\n  File \"c:\\Users\\limfy\\anaconda3\\Lib\\site-packages\\keras\\src\\utils\\traceback_utils.py\", line 70, in error_handler\n    raise e.with_traceback(filtered_tb) from None\n  File \"C:\\Users\\limfy\\AppData\\Local\\Temp\\__autograph_generated_file4vc023t_.py\", line 18, in tf__train_function\n    raise\nValueError: in user code:\n\n    File \"c:\\Users\\limfy\\anaconda3\\Lib\\site-packages\\keras\\src\\engine\\training.py\", line 1338, in train_function  *\n        return step_function(self, iterator)\n    File \"c:\\Users\\limfy\\anaconda3\\Lib\\site-packages\\keras\\src\\engine\\training.py\", line 1322, in step_function  **\n        outputs = model.distribute_strategy.run(run_step, args=(data,))\n    File \"c:\\Users\\limfy\\anaconda3\\Lib\\site-packages\\keras\\src\\engine\\training.py\", line 1303, in run_step  **\n        outputs = model.train_step(data)\n    File \"c:\\Users\\limfy\\anaconda3\\Lib\\site-packages\\keras\\src\\engine\\training.py\", line 1080, in train_step\n        y_pred = self(x, training=True)\n    File \"c:\\Users\\limfy\\anaconda3\\Lib\\site-packages\\keras\\src\\utils\\traceback_utils.py\", line 70, in error_handler\n        raise e.with_traceback(filtered_tb) from None\n    File \"c:\\Users\\limfy\\anaconda3\\Lib\\site-packages\\keras\\src\\engine\\input_spec.py\", line 235, in assert_input_compatibility\n        raise ValueError(\n\n    ValueError: Exception encountered when calling layer 'sequential' (type Sequential).\n    \n    Input 0 of layer \"lstm\" is incompatible with the layer: expected ndim=3, found ndim=2. Full shape received: (None, 15)\n    \n    Call arguments received by layer 'sequential' (type Sequential):\n      \u2022 inputs=tf.Tensor(shape=(None, 15), dtype=float64)\n      \u2022 training=True\n      \u2022 mask=None\n\n"}